Workbook

Sheet Explanations and FAQ
A1: End Game | B1: My objective in this spreadsheet is to compute the annual returns you would have earned on major financial asset classses, on an annual basis, inclusive of both cash payout during the year and the price appreciation.
A3: Explanations, by asset class
A4: Stocks (Large Cap) | B4: I use the S&P 500, which was created in 1957, and then back fill the data using other indices of large market cap companies that existed prior. Each year, I compute the annual return, by first computing the dividend yield by dividing the dividends paid and the price change in the index, by the level of the index at the start of the year. Thus, if the index starts at 1000, and increases to 1080, while delivering a dividend of 5, my annual return = (1080-1000+5)/1000 = 8.5%
A5: Stocks (Small Cap) | B5: I use the value-weighted bottom decile of US stocks, as estimated and reported by Ken French on his amazing data page, for annual returns every year from 1928 to the most recent year.
A6: US T.Bond | B6: I use the 10-year US treasury bond, since it is the only longer maturity bond with an uninterrupted history going back in time. For the data, I use the yields on a constant-maturrity 10-year bond, which can be found on FRED (the Federal Reserve website). I convert the yield into a return, by repricing the bond, issued at par at the prior year's yield, with the new yield, while keeping the maturity constant at 10 years. Thus, if the yield goes from 2.5% to 3%, I first price a 2.5%, 10 year coupon bond with a 3% interest rate, and subtract this number from the par value of the bond which is $1000. That gives me the price change. Adding the 3% coupon for the current year gives me the total return.
A7: US T.Bill | B7: I use the 3-month US treasury bill, again choosing it over the 6-month because of longevity. While I used to report the end of the year number as the return on the T.Bill for the year, I have replaced that with the average T.Bill rate over the year, since that is a better representation.
A8: Aaa & Baa Corporate Bond | B8: I obtain the yield on a Moody's Aaa and Baa corporate bond yields from FRED and then compute the return on the bond, using the same approach that I use for the US T.Bond.
A9: Real Estate | B9: I use the home price data that Robert Shiller reports on his webpage to compute a real estate return on residential real estate. That series has now morphed into the Case-Shiller Index. Note that this return is just price appreciation, and will understate the returns on real estate by the cash flow return (from rental income) each year.
A10: Gold | B10: Year-end prices for gold, per oz,
A11: Inflation Rate | B11: I use the CPI for all urban consumers, reported on FRED. I use the non seasonally adjusted numbers, because they go back to 1914. Seasonal adjustments began in 1948.
A12: Real Returns | B12: For each of the data series. I computre a real return by removing the inflatin for the year from the nominal return, using (1+ Nominal Rate)/ (1+Inflation Rate) -1.
A13: Arithmetic Average Return | B13: A simple average of the annual returns over the specified period (10 yrs, 50 yrs etc.)
A14: Geometric Average Return | B14: A compounded average of the returns over the period. This is most simply computed by dividing the value you would have at the end of the period by the value at the beginning and then computing the compouded average. To compute the cumulated value on both stocks and bonds, I assume that dividends/coupons get reinvested back.
A15: Risk Premium | B15: The risk premium is the difference in the annualized return on stocks and the annualized return on T.Bonds and on T.Bills over the specified period.
A17: FAQ
A18: How precise are the annual numbers? | B18: Since the S&P and US treasuries are liquid and the underlying data is widely dispersed, the annual numbers are reliable.
A19: How good as the averages as predictors? | B19: The returns, especially on stocks and bonds, are noisy, with up years and down years. The averages that have been computed come with error, and I have computed standard errros in each of the numbers (especially the risk premiums). Note that even with the longest data series, there is substantial standard error and it becomes explosively large for shorter periods.
A20: Why do you keep the maturity of the 10-year bond unchanged, when you compute the return on the bond? | B20: Normally, when you buy a 10-year bond and hold it for a year, you will end up with a 9-year bond. While I could compute the return using a 9-year maturity, and the answer will be fairly close to what I report, I want to keep the 10-year rmaturity going for consistency in my risk premium computation. Put simply, think of the return on the 10-year bond as the one you would have if the coupon changed, but the maturity is reset to 10 year at the end of the year.

Sheet Returns by year
B1: Annual Returns on Investments in | I1: Annual Risk Premium
A2: Year | B2: S&P 500 (includes dividends) | C2: US Small cap (bottom decile) | D2: 3-month T.Bill | E2: US T. Bond (10-year) | F2: Baa Corporate Bond | G2: Real Estate | H2: Gold* | I2: Stocks - Bills | J2: Stocks - Bonds | K2: Small Cap Premium (S&P 500 minus Bottom Decile) | L2: Stocks - Baa Corp Bond
A3: 1928 | B3: =('S&P 500 & Raw Data'!B4-'S&P 500 & Raw Data'!B3+'S&P 500 & Raw Data'!C4)/'S&P 500 & Raw Data'!B3 -> 0.43811155 | C3: ='Small Cap'!B2 -> 0.6215 | D3: 0.0308 | E3: ='S&P 500 & Raw Data'!F4 -> 0.0083547086 | F3: ='S&P 500 & Raw Data'!J4 -> 0.032195515 | G3: ='Home Prices'!B4/'Home Prices'!B3-1 -> 0.014910537 | H3: ='Gold Prices'!B3/'Gold Prices'!B2-1 -> 0.00096899225 | I3: =B3-D3 -> 0.40731155 | J3: =B3-E3 -> 0.42975684 | K3: =Table1[[#This Row],[US Small cap (bottom decile)]]-Table1[[#This Row],[S&P 500 (includes dividends)]] -> 0.18338845 | L3: =B3-F3 -> 0.40591604
A4: 1929 | B4: =('S&P 500 & Raw Data'!B5-'S&P 500 & Raw Data'!B4+'S&P 500 & Raw Data'!C5)/'S&P 500 & Raw Data'!B4 -> -0.082979466 | C4: ='Small Cap'!B3 -> -0.4608 | D4: 0.0316 | E4: ='S&P 500 & Raw Data'!F5 -> 0.042038042 | F4: ='S&P 500 & Raw Data'!J5 -> 0.030178562 | G4: ='Home Prices'!B5/'Home Prices'!B4-1 -> -0.020568071 | H4: ='Gold Prices'!B4/'Gold Prices'!B3-1 -> -0.0014520813 | I4: =B4-D4 -> -0.11457947 | J4: =B4-E4 -> -0.12501751 | K4: =Table1[[#This Row],[US Small cap (bottom decile)]]-Table1[[#This Row],[S&P 500 (includes dividends)]] -> -0.37782053 | L4: =B4-F4 -> -0.11315803
A5: 1930 | B5: =('S&P 500 & Raw Data'!B6-'S&P 500 & Raw Data'!B5+'S&P 500 & Raw Data'!C6)/'S&P 500 & Raw Data'!B5 -> -0.25123636 | C5: ='Small Cap'!B4 -> -0.4835 | D5: 0.0455 | E5: ='S&P 500 & Raw Data'!F6 -> 0.045409314 | F5: ='S&P 500 & Raw Data'!J6 -> 0.0053978095 | G5: ='Home Prices'!B6/'Home Prices'!B5-1 -> -0.043 | H5: ='Gold Prices'!B5/'Gold Prices'!B4-1 -> 0.00096946195 | I5: =B5-D5 -> -0.29673636 | J5: =B5-E5 -> -0.29664568 | K5: =Table1[[#This Row],[US Small cap (bottom decile)]]-Table1[[#This Row],[S&P 500 (includes dividends)]] -> -0.23226364 | L5: =B5-F5 -> -0.25663417
A6: 1931 | B6: =('S&P 500 & Raw Data'!B7-'S&P 500 & Raw Data'!B6+'S&P 500 & Raw Data'!C7)/'S&P 500 & Raw Data'!B6 -> -0.43837549 | C6: ='Small Cap'!B5 -> -0.4362 | D6: 0.0231 | E6: ='S&P 500 & Raw Data'!F7 -> -0.02558856 | F6: ='S&P 500 & Raw Data'!J7 -> -0.15680775 | G6: ='Home Prices'!B7/'Home Prices'!B6-1 -> -0.081504702 | H6: ='Gold Prices'!B6/'Gold Prices'!B5-1 -> -0.17384988 | I6: =B6-D6 -> -0.46147549 | J6: =B6-E6 -> -0.41278693 | K6: =Table1[[#This Row],[US Small cap (bottom decile)]]-Table1[[#This Row],[S&P 500 (includes dividends)]] -> 0.0021754889 | L6: =B6-F6 -> -0.28156774
A7: 1932 | B7: =('S&P 500 & Raw Data'!B8-'S&P 500 & Raw Data'!B7+'S&P 500 & Raw Data'!C8)/'S&P 500 & Raw Data'!B7 -> -0.086423645 | C7: ='Small Cap'!B6 -> 0.2865 | D7: 0.0107 | E7: ='S&P 500 & Raw Data'!F8 -> 0.08790307 | F7: ='S&P 500 & Raw Data'!J8 -> 0.23589602 | G7: ='Home Prices'!B8/'Home Prices'!B7-1 -> -0.10466439 | H7: ='Gold Prices'!B7/'Gold Prices'!B6-1 -> 0.21277843 | I7: =B7-D7 -> -0.097123645 | J7: =B7-E7 -> -0.17432672 | K7: =Table1[[#This Row],[US Small cap (bottom decile)]]-Table1[[#This Row],[S&P 500 (includes dividends)]] -> 0.37292365 | L7: =B7-F7 -> -0.32231966
A8: 1933 | B8: =('S&P 500 & Raw Data'!B9-'S&P 500 & Raw Data'!B8+'S&P 500 & Raw Data'!C9)/'S&P 500 & Raw Data'!B8 -> 0.49982225 | C8: ='Small Cap'!B7 -> 1.466 | D8: 0.0096 | E8: ='S&P 500 & Raw Data'!F9 -> 0.018552721 | F8: ='S&P 500 & Raw Data'!J9 -> 0.12966894 | G8: ='Home Prices'!B9/'Home Prices'!B8-1 -> -0.038119441 | H8: ='Gold Prices'!B8/'Gold Prices'!B7-1 -> 0.27259546 | I8: =B8-D8 -> 0.49022225 | J8: =B8-E8 -> 0.48126953 | K8: =Table1[[#This Row],[US Small cap (bottom decile)]]-Table1[[#This Row],[S&P 500 (includes dividends)]] -> 0.96617775 | L8: =B8-F8 -> 0.37015332
A9: 1934 | B9: =('S&P 500 & Raw Data'!B10-'S&P 500 & Raw Data'!B9+'S&P 500 & Raw Data'!C10)/'S&P 500 & Raw Data'!B9 -> -0.011885657 | C9: ='Small Cap'!B8 -> 0.2307 | D9: ='T. Bill rates'!C12 -> 0.0027833333 | E9: ='S&P 500 & Raw Data'!F10 -> 0.079634426 | F9: ='S&P 500 & Raw Data'!J10 -> 0.18816429 | G9: ='Home Prices'!B10/'Home Prices'!B9-1 -> 0.029062087 | H9: ='Gold Prices'!B9/'Gold Prices'!B8-1 -> 0.31750855 | I9: =B9-D9 -> -0.01466899 | J9: =B9-E9 -> -0.091520083 | K9: =Table1[[#This Row],[US Small cap (bottom decile)]]-Table1[[#This Row],[S&P 500 (includes dividends)]] -> 0.24258566 | L9: =B9-F9 -> -0.20004995
A10: 1935 | B10: =('S&P 500 & Raw Data'!B11-'S&P 500 & Raw Data'!B10+'S&P 500 & Raw Data'!C11)/'S&P 500 & Raw Data'!B10 -> 0.46740421 | C10: ='Small Cap'!B9 -> 0.549 | D10: ='T. Bill rates'!C13 -> 0.001675 | E10: ='S&P 500 & Raw Data'!F11 -> 0.044720477 | F10: ='S&P 500 & Raw Data'!J11 -> 0.13307732 | G10: ='Home Prices'!B11/'Home Prices'!B10-1 -> 0.097658337 | H10: ='Gold Prices'!B10/'Gold Prices'!B9-1 -> 0.0043240127 | I10: =B10-D10 -> 0.46572921 | J10: =B10-E10 -> 0.42268373 | K10: =Table1[[#This Row],[US Small cap (bottom decile)]]-Table1[[#This Row],[S&P 500 (includes dividends)]] -> 0.081595789 | L10: =B10-F10 -> 0.33432689
A11: 1936 | B11: =('S&P 500 & Raw Data'!B12-'S&P 500 & Raw Data'!B11+'S&P 500 & Raw Data'!C12)/'S&P 500 & Raw Data'!B11 -> 0.3194341 | C11: ='Small Cap'!B10 -> 0.9641 | D11: ='T. Bill rates'!C14 -> 0.001725 | E11: ='S&P 500 & Raw Data'!F12 -> 0.050178754 | F11: ='S&P 500 & Raw Data'!J12 -> 0.11383816 | G11: ='Home Prices'!B12/'Home Prices'!B11-1 -> 0.032186015 | H11: ='Gold Prices'!B11/'Gold Prices'!B10-1 -> 0.00086107922 | I11: =B11-D11 -> 0.3177091 | J11: =B11-E11 -> 0.26925535 | K11: =Table1[[#This Row],[US Small cap (bottom decile)]]-Table1[[#This Row],[S&P 500 (includes dividends)]] -> 0.6446659 | L11: =B11-F11 -> 0.20559594
A12: 1937 | B12: =('S&P 500 & Raw Data'!B13-'S&P 500 & Raw Data'!B12+'S&P 500 & Raw Data'!C13)/'S&P 500 & Raw Data'!B12 -> -0.35336729 | C12: ='Small Cap'!B11 -> -0.5394 | D12: ='T. Bill rates'!C15 -> 0.0027583333 | E12: ='S&P 500 & Raw Data'!F13 -> 0.013791461 | F12: ='S&P 500 & Raw Data'!J13 -> -0.044161917 | G12: ='Home Prices'!B13/'Home Prices'!B12-1 -> 0.025633912 | H12: ='Gold Prices'!B12/'Gold Prices'!B11-1 -> -0.0022942357 | I12: =B12-D12 -> -0.35612562 | J12: =B12-E12 -> -0.36715875 | K12: =Table1[[#This Row],[US Small cap (bottom decile)]]-Table1[[#This Row],[S&P 500 (includes dividends)]] -> -0.18603271 | L12: =B12-F12 -> -0.30920537
A13: 1938 | B13: =('S&P 500 & Raw Data'!B14-'S&P 500 & Raw Data'!B13+'S&P 500 & Raw Data'!C14)/'S&P 500 & Raw Data'!B13 -> 0.29282654 | C13: ='Small Cap'!B12 -> 0.0516 | D13: ='T. Bill rates'!C16 -> 0.00065 | E13: ='S&P 500 & Raw Data'!F14 -> 0.042132485 | F13: ='S&P 500 & Raw Data'!J14 -> 0.092358817 | G13: ='Home Prices'!B14/'Home Prices'!B13-1 -> -0.0087368136 | H13: ='Gold Prices'!B13/'Gold Prices'!B12-1 -> 0.0017246335 | I13: =B13-D13 -> 0.29217654 | J13: =B13-E13 -> 0.25069405 | K13: =Table1[[#This Row],[US Small cap (bottom decile)]]-Table1[[#This Row],[S&P 500 (includes dividends)]] -> -0.24122654 | L13: =B13-F13 -> 0.20046772
A14: 1939 | B14: =('S&P 500 & Raw Data'!B15-'S&P 500 & Raw Data'!B14+'S&P 500 & Raw Data'!C15)/'S&P 500 & Raw Data'!B14 -> -0.010975647 | C14: ='Small Cap'!B13 -> -0.0486 | D14: ='T. Bill rates'!C17 -> 0.00045833333 | E14: ='S&P 500 & Raw Data'!F15 -> 0.044122614 | F14: ='S&P 500 & Raw Data'!J15 -> 0.079831378 | G14: ='Home Prices'!B15/'Home Prices'!B14-1 -> -0.013016072 | H14: ='Gold Prices'!B14/'Gold Prices'!B13-1 -> -0.012338594 | I14: =B14-D14 -> -0.01143398 | J14: =B14-E14 -> -0.055098261 | K14: =Table1[[#This Row],[US Small cap (bottom decile)]]-Table1[[#This Row],[S&P 500 (includes dividends)]] -> -0.037624353 | L14: =B14-F14 -> -0.090807025
A15: 1940 | B15: =('S&P 500 & Raw Data'!B16-'S&P 500 & Raw Data'!B15+'S&P 500 & Raw Data'!C16)/'S&P 500 & Raw Data'!B15 -> -0.10672873 | C15: ='Small Cap'!B14 -> -0.3288 | D15: ='T. Bill rates'!C18 -> 0.00035833333 | E15: ='S&P 500 & Raw Data'!F16 -> 0.054024816 | F15: ='S&P 500 & Raw Data'!J16 -> 0.086481372 | G15: ='Home Prices'!B16/'Home Prices'!B15-1 -> 0.033066077 | H15: ='Gold Prices'!B15/'Gold Prices'!B14-1 -> -0.016560139 | I15: =B15-D15 -> -0.10708707 | J15: =B15-E15 -> -0.16075355 | K15: =Table1[[#This Row],[US Small cap (bottom decile)]]-Table1[[#This Row],[S&P 500 (includes dividends)]] -> -0.22207127 | L15: =B15-F15 -> -0.1932101
A16: 1941 | B16: =('S&P 500 & Raw Data'!B17-'S&P 500 & Raw Data'!B16+'S&P 500 & Raw Data'!C17)/'S&P 500 & Raw Data'!B16 -> -0.12771456 | C16: ='Small Cap'!B15 -> -0.0675 | D16: ='T. Bill rates'!C19 -> 0.0012916667 | E16: ='S&P 500 & Raw Data'!F17 -> -0.020221976 | F16: ='S&P 500 & Raw Data'!J17 -> 0.050071729 | G16: ='Home Prices'!B17/'Home Prices'!B16-1 -> -0.083846277 | H16: ='Gold Prices'!B16/'Gold Prices'!B15-1 -> 0 | I16: =B16-D16 -> -0.12900622 | J16: =B16-E16 -> -0.10749258 | K16: =Table1[[#This Row],[US Small cap (bottom decile)]]-Table1[[#This Row],[S&P 500 (includes dividends)]] -> 0.060214556 | L16: =B16-F16 -> -0.17778628
A17: 1942 | B17: =('S&P 500 & Raw Data'!B18-'S&P 500 & Raw Data'!B17+'S&P 500 & Raw Data'!C18)/'S&P 500 & Raw Data'!B17 -> 0.19173763 | C17: ='Small Cap'!B16 -> 0.6301 | D17: ='T. Bill rates'!C20 -> 0.003425 | E17: ='S&P 500 & Raw Data'!F18 -> 0.022948682 | F17: ='S&P 500 & Raw Data'!J18 -> 0.05179901 | G17: ='Home Prices'!B18/'Home Prices'!B17-1 -> 0.033330412 | H17: ='Gold Prices'!B17/'Gold Prices'!B16-1 -> 0 | I17: =B17-D17 -> 0.18831263 | J17: =B17-E17 -> 0.16878895 | K17: =Table1[[#This Row],[US Small cap (bottom decile)]]-Table1[[#This Row],[S&P 500 (includes dividends)]] -> 0.43836237 | L17: =B17-F17 -> 0.13993862
A18: 1943 | B18: =('S&P 500 & Raw Data'!B19-'S&P 500 & Raw Data'!B18+'S&P 500 & Raw Data'!C19)/'S&P 500 & Raw Data'!B18 -> 0.2506131 | C18: ='Small Cap'!B17 -> 1.4302 | D18: ='T. Bill rates'!C21 -> 0.0038 | E18: ='S&P 500 & Raw Data'!F19 -> 0.0249 | F18: ='S&P 500 & Raw Data'!J19 -> 0.080446701 | G18: ='Home Prices'!B19/'Home Prices'!B18-1 -> 0.1144626 | H18: ='Gold Prices'!B18/'Gold Prices'!B17-1 -> 0 | I18: =B18-D18 -> 0.2468131 | J18: =B18-E18 -> 0.2257131 | K18: =Table1[[#This Row],[US Small cap (bottom decile)]]-Table1[[#This Row],[S&P 500 (includes dividends)]] -> 1.1795869 | L18: =B18-F18 -> 0.1701664
A19: 1944 | B19: =('S&P 500 & Raw Data'!B20-'S&P 500 & Raw Data'!B19+'S&P 500 & Raw Data'!C20)/'S&P 500 & Raw Data'!B19 -> 0.19030677 | C19: ='Small Cap'!B18 -> 0.7115 | D19: ='T. Bill rates'!C22 -> 0.0038 | E19: ='S&P 500 & Raw Data'!F20 -> 0.025776112 | F19: ='S&P 500 & Raw Data'!J20 -> 0.065658636 | G19: ='Home Prices'!B20/'Home Prices'!B19-1 -> 0.16584227 | H19: ='Gold Prices'!B19/'Gold Prices'!B18-1 -> 0 | I19: =B19-D19 -> 0.18650677 | J19: =B19-E19 -> 0.16453066 | K19: =Table1[[#This Row],[US Small cap (bottom decile)]]-Table1[[#This Row],[S&P 500 (includes dividends)]] -> 0.52119323 | L19: =B19-F19 -> 0.12464813
A20: 1945 | B20: =('S&P 500 & Raw Data'!B21-'S&P 500 & Raw Data'!B20+'S&P 500 & Raw Data'!C21)/'S&P 500 & Raw Data'!B20 -> 0.35821084 | C20: ='Small Cap'!B19 -> 0.9441 | D20: ='T. Bill rates'!C23 -> 0.0038 | E20: ='S&P 500 & Raw Data'!F21 -> 0.038044173 | F20: ='S&P 500 & Raw Data'!J21 -> 0.067998655 | G20: ='Home Prices'!B21/'Home Prices'!B20-1 -> 0.11777376 | H20: ='Gold Prices'!B20/'Gold Prices'!B19-1 -> 0.025406204 | I20: =B20-D20 -> 0.35441084 | J20: =B20-E20 -> 0.32016667 | K20: =Table1[[#This Row],[US Small cap (bottom decile)]]-Table1[[#This Row],[S&P 500 (includes dividends)]] -> 0.58588916 | L20: =B20-F20 -> 0.29021219
... A100: 2025 | B100: =('S&P 500 & Raw Data'!B101-'S&P 500 & Raw Data'!B100+'S&P 500 & Raw Data'!C101)/'S&P 500 & Raw Data'!B100 -> 0.17723658 | C100: ='Small Cap'!B99 -> 0.1653 | D100: ='T. Bill rates'!C103 -> 0.0421 | E100: ='S&P 500 & Raw Data'!F101 -> 0.077954809 | F100: ='S&P 500 & Raw Data'!J101 -> 0.069627321 | G100: ='Home Prices'!B101/'Home Prices'!B100-1 -> 0.015757066 | H100: ='Gold Prices'!B100/'Gold Prices'!B99-1 -> 0.66215792 | I100: =B100-D100 -> 0.13513658 | J100: =B100-E100 -> 0.099281774 | K100: =Table1[[#This Row],[US Small cap (bottom decile)]]-Table1[[#This Row],[S&P 500 (includes dividends)]] -> -0.011936582 | L100: =B100-F100 -> 0.10760926

Sheet S&P 500 & Raw Data
A2: Year | B2: S&P 500 | C2: Dividends | D2: Dividend Yield | E2: T.Bond rate | F2: Return on bond | G2: Aaa Bond Rate | H2: Return on Aaa | I2: Baa Bond Rate | J2: Return on Baa | K2: Returns on Real Estate
A3: 1927 | B3: 17.66 | C3: =D3*B3 -> 0.6181 | D3: 0.035 | E3: 0.0317 | G3: ='Moody''s Rates'!C20 -> 0.0446 | I3: ='Moody''s Rates'!K20 -> 0.0532
A4: 1928 | B4: 24.35 | C4: =D4*B4 -> 1.04705 | D4: 0.043 | E4: 0.0345 | F4: =((E3*(1-(1+E4)^(-10))/E4+1/(1+E4)^10)-1)+E3 -> 0.0083547086 | G4: ='Moody''s Rates'!C21 -> 0.0461 | H4: =((G3*(1-(1+G4)^(-10))/G4+1/(1+G4)^10)-1)+G3 -> 0.032794856 | I4: ='Moody''s Rates'!K21 -> 0.056 | J4: =((I3*(1-(1+I4)^(-10))/I4+1/(1+I4)^10)-1)+I3 -> 0.032195515 | K4: ='Home Prices (Raw Data)'!C48 -> 0.014910639
A5: 1929 | B5: 21.45 | C5: =D5*B5 -> 0.87945 | D5: 0.041 | E5: 0.0336 | F5: =((E4*(1-(1+E5)^(-10))/E5+1/(1+E5)^10)-1)+E4 -> 0.042038042 | G5: ='Moody''s Rates'!C22 -> 0.0467 | H5: =((G4*(1-(1+G5)^(-10))/G5+1/(1+G5)^10)-1)+G4 -> 0.041391804 | I5: ='Moody''s Rates'!K22 -> 0.0595 | J5: =((I4*(1-(1+I5)^(-10))/I5+1/(1+I5)^10)-1)+I4 -> 0.030178562 | K5: ='Home Prices (Raw Data)'!C49 -> -0.020568075
A6: 1930 | B6: 15.34 | C6: =D6*B6 -> 0.72098 | D6: 0.047 | E6: 0.0322 | F6: =((E5*(1-(1+E6)^(-10))/E6+1/(1+E6)^10)-1)+E5 -> 0.045409314 | G6: ='Moody''s Rates'!C23 -> 0.0452 | H6: =((G5*(1-(1+G6)^(-10))/G6+1/(1+G6)^10)-1)+G5 -> 0.058557414 | I6: ='Moody''s Rates'!K23 -> 0.0671 | J6: =((I5*(1-(1+I6)^(-10))/I6+1/(1+I6)^10)-1)+I5 -> 0.0053978095 | K6: ='Home Prices (Raw Data)'!C50 -> -0.042999993
A7: 1931 | B7: 8.12 | C7: =D7*B7 -> 0.49532 | D7: 0.061 | E7: 0.0393 | F7: =((E6*(1-(1+E7)^(-10))/E7+1/(1+E7)^10)-1)+E6 -> -0.02558856 | G7: ='Moody''s Rates'!C24 -> 0.0532 | H7: =((G6*(1-(1+G7)^(-10))/G7+1/(1+G7)^10)-1)+G6 -> -0.015625061 | I7: ='Moody''s Rates'!K24 -> 0.1042 | J7: =((I6*(1-(1+I7)^(-10))/I7+1/(1+I7)^10)-1)+I6 -> -0.15680775 | K7: ='Home Prices (Raw Data)'!C51 -> -0.081504822
A8: 1932 | B8: 6.92 | C8: =D8*B8 -> 0.49824 | D8: 0.072 | E8: 0.0335 | F8: =((E7*(1-(1+E8)^(-10))/E8+1/(1+E8)^10)-1)+E7 -> 0.08790307 | G8: ='Moody''s Rates'!C25 -> 0.0459 | H8: =((G7*(1-(1+G8)^(-10))/G8+1/(1+G8)^10)-1)+G7 -> 0.11070808 | I8: ='Moody''s Rates'!K25 -> 0.0842 | J8: =((I7*(1-(1+I8)^(-10))/I8+1/(1+I8)^10)-1)+I7 -> 0.23589602 | K8: ='Home Prices (Raw Data)'!C52 -> -0.10466428
A9: 1933 | B9: 9.97 | C9: =D9*B9 -> 0.40877 | D9: 0.041 | E9: 0.0353 | F9: =((E8*(1-(1+E9)^(-10))/E9+1/(1+E9)^10)-1)+E8 -> 0.018552721 | G9: ='Moody''s Rates'!C26 -> 0.045 | H9: =((G8*(1-(1+G9)^(-10))/G9+1/(1+G9)^10)-1)+G8 -> 0.053021446 | I9: ='Moody''s Rates'!K26 -> 0.0775 | J9: =((I8*(1-(1+I9)^(-10))/I9+1/(1+I9)^10)-1)+I8 -> 0.12966894 | K9: ='Home Prices (Raw Data)'!C53 -> -0.03811948
A10: 1934 | B10: 9.5 | C10: =D10*B10 -> 0.3515 | D10: 0.037 | E10: 0.0301 | F10: =((E9*(1-(1+E10)^(-10))/E10+1/(1+E10)^10)-1)+E9 -> 0.079634426 | G10: ='Moody''s Rates'!C27 -> 0.0381 | H10: =((G9*(1-(1+G10)^(-10))/G10+1/(1+G10)^10)-1)+G9 -> 0.1014983 | I10: ='Moody''s Rates'!K27 -> 0.0623 | J10: =((I9*(1-(1+I10)^(-10))/I10+1/(1+I10)^10)-1)+I9 -> 0.18816429 | K10: ='Home Prices (Raw Data)'!C54 -> 0.029062073
A11: 1935 | B11: 13.43 | C11: =D11*B11 -> 0.51034 | D11: 0.038 | E11: 0.0284 | F11: =((E10*(1-(1+E11)^(-10))/E11+1/(1+E11)^10)-1)+E10 -> 0.044720477 | G11: ='Moody''s Rates'!C28 -> 0.0344 | H11: =((G10*(1-(1+G11)^(-10))/G11+1/(1+G11)^10)-1)+G10 -> 0.068964709 | I11: ='Moody''s Rates'!K28 -> 0.053 | J11: =((I10*(1-(1+I11)^(-10))/I11+1/(1+I11)^10)-1)+I10 -> 0.13307732 | K11: ='Home Prices (Raw Data)'!C55 -> 0.097658281
A12: 1936 | B12: 17.18 | C12: 0.54 | D12: =C12/B12 -> 0.031431898 | E12: 0.0259 | F12: =((E11*(1-(1+E12)^(-10))/E12+1/(1+E12)^10)-1)+E11 -> 0.050178754 | G12: ='Moody''s Rates'!C29 -> 0.031 | H12: =((G11*(1-(1+G12)^(-10))/G12+1/(1+G12)^10)-1)+G11 -> 0.063255237 | I12: ='Moody''s Rates'!K29 -> 0.0453 | J12: =((I11*(1-(1+I12)^(-10))/I12+1/(1+I12)^10)-1)+I11 -> 0.11383816 | K12: ='Home Prices (Raw Data)'!C56 -> 0.032186067
A13: 1937 | B13: 10.55 | C13: =D13*B13 -> 0.55915 | D13: 0.053 | E13: 0.0273 | F13: =((E12*(1-(1+E13)^(-10))/E13+1/(1+E13)^10)-1)+E12 -> 0.013791461 | G13: ='Moody''s Rates'!C30 -> 0.0321 | H13: =((G12*(1-(1+G13)^(-10))/G13+1/(1+G13)^10)-1)+G12 -> 0.021716542 | I13: ='Moody''s Rates'!K30 -> 0.0573 | J13: =((I12*(1-(1+I13)^(-10))/I13+1/(1+I13)^10)-1)+I12 -> -0.044161917 | K13: ='Home Prices (Raw Data)'!C57 -> 0.025633982
A14: 1938 | B14: 13.14 | C14: =D14*B14 -> 0.49932 | D14: 0.038 | E14: 0.0256 | F14: =((E13*(1-(1+E14)^(-10))/E14+1/(1+E14)^10)-1)+E13 -> 0.042132485 | G14: ='Moody''s Rates'!C31 -> 0.0308 | H14: =((G13*(1-(1+G14)^(-10))/G14+1/(1+G14)^10)-1)+G13 -> 0.043144127 | I14: ='Moody''s Rates'!K31 -> 0.0527 | J14: =((I13*(1-(1+I14)^(-10))/I14+1/(1+I14)^10)-1)+I13 -> 0.092358817 | K14: ='Home Prices (Raw Data)'!C58 -> -0.0087369579
A15: 1939 | B15: 12.46 | C15: =D15*B15 -> 0.53578 | D15: 0.043 | E15: 0.0235 | F15: =((E14*(1-(1+E15)^(-10))/E15+1/(1+E15)^10)-1)+E14 -> 0.044122614 | G15: ='Moody''s Rates'!C32 -> 0.0294 | H15: =((G14*(1-(1+G15)^(-10))/G15+1/(1+G15)^10)-1)+G14 -> 0.042778935 | I15: ='Moody''s Rates'!K32 -> 0.0492 | J15: =((I14*(1-(1+I15)^(-10))/I15+1/(1+I15)^10)-1)+I14 -> 0.079831378 | K15: ='Home Prices (Raw Data)'!C59 -> -0.013016039
A16: 1940 | B16: 10.58 | C16: =D16*B16 -> 0.55016 | D16: 0.052 | E16: 0.0201 | F16: =((E15*(1-(1+E16)^(-10))/E16+1/(1+E16)^10)-1)+E15 -> 0.054024816 | G16: ='Moody''s Rates'!C33 -> 0.0271 | H16: =((G15*(1-(1+G16)^(-10))/G16+1/(1+G16)^10)-1)+G15 -> 0.049313057 | I16: ='Moody''s Rates'!K33 -> 0.0445 | J16: =((I15*(1-(1+I16)^(-10))/I16+1/(1+I16)^10)-1)+I15 -> 0.086481372 | K16: ='Home Prices (Raw Data)'!C60 -> 0.033066027
A17: 1941 | B17: 8.69 | C17: =D17*B17 -> 0.53878 | D17: 0.062 | E17: 0.0247 | F17: =((E16*(1-(1+E17)^(-10))/E17+1/(1+E17)^10)-1)+E16 -> -0.020221976 | G17: ='Moody''s Rates'!C34 -> 0.028 | H17: =((G16*(1-(1+G17)^(-10))/G17+1/(1+G17)^10)-1)+G16 -> 0.019343859 | I17: ='Moody''s Rates'!K34 -> 0.0438 | J17: =((I16*(1-(1+I17)^(-10))/I17+1/(1+I17)^10)-1)+I16 -> 0.050071729 | K17: ='Home Prices (Raw Data)'!C61 -> -0.08384617
A18: 1942 | B18: 9.77 | C18: =D18*B18 -> 0.5862 | D18: 0.06 | E18: 0.0249 | F18: =((E17*(1-(1+E18)^(-10))/E18+1/(1+E18)^10)-1)+E17 -> 0.022948682 | G18: ='Moody''s Rates'!C35 -> 0.0281 | H18: =((G17*(1-(1+G18)^(-10))/G18+1/(1+G18)^10)-1)+G17 -> 0.027138648 | I18: ='Moody''s Rates'!K35 -> 0.0428 | J18: =((I17*(1-(1+I18)^(-10))/I18+1/(1+I18)^10)-1)+I17 -> 0.05179901 | K18: ='Home Prices (Raw Data)'!C62 -> 0.033330352
A19: 1943 | B19: 11.67 | C19: =D19*B19 -> 0.54849 | D19: 0.047 | E19: 0.0249 | F19: =((E18*(1-(1+E19)^(-10))/E19+1/(1+E19)^10)-1)+E18 -> 0.0249 | G19: ='Moody''s Rates'!C36 -> 0.0274 | H19: =((G18*(1-(1+G19)^(-10))/G19+1/(1+G19)^10)-1)+G18 -> 0.03415116 | I19: ='Moody''s Rates'!K36 -> 0.0382 | J19: =((I18*(1-(1+I19)^(-10))/I19+1/(1+I19)^10)-1)+I18 -> 0.080446701 | K19: ='Home Prices (Raw Data)'!C63 -> 0.1144627
A20: 1944 | B20: 13.28 | C20: =D20*B20 -> 0.61088 | D20: 0.046 | E20: 0.0248 | F20: =((E19*(1-(1+E20)^(-10))/E20+1/(1+E20)^10)-1)+E19 -> 0.025776112 | G20: ='Moody''s Rates'!C37 -> 0.027 | H20: =((G19*(1-(1+G20)^(-10))/G20+1/(1+G20)^10)-1)+G19 -> 0.030864921 | I20: ='Moody''s Rates'!K37 -> 0.0349 | J20: =((I19*(1-(1+I20)^(-10))/I20+1/(1+I20)^10)-1)+I19 -> 0.065658636 | K20: ='Home Prices (Raw Data)'!C64 -> 0.16584229
A21: 1945 | B21: 17.36 | C21: =D21*B21 -> 0.67704 | D21: 0.039 | E21: 0.0233 | F21: =((E20*(1-(1+E21)^(-10))/E21+1/(1+E21)^10)-1)+E20 -> 0.038044173 | G21: ='Moody''s Rates'!C38 -> 0.0261 | H21: =((G20*(1-(1+G21)^(-10))/G21+1/(1+G21)^10)-1)+G20 -> 0.034832273 | I21: ='Moody''s Rates'!K38 -> 0.031 | J21: =((I20*(1-(1+I21)^(-10))/I21+1/(1+I21)^10)-1)+I20 -> 0.067998655 | K21: ='Home Prices (Raw Data)'!C65 -> 0.11777376
A22: 1946 | B22: 15.3 | C22: =D22*B22 -> 0.5967 | D22: 0.039 | E22: 0.0224 | F22: =((E21*(1-(1+E22)^(-10))/E22+1/(1+E22)^10)-1)+E21 -> 0.031283745 | G22: ='Moody''s Rates'!C39 -> 0.0261 | H22: =((G21*(1-(1+G22)^(-10))/G22+1/(1+G22)^10)-1)+G21 -> 0.0261 | I22: ='Moody''s Rates'!K39 -> 0.0317 | J22: =((I21*(1-(1+I22)^(-10))/I22+1/(1+I22)^10)-1)+I21 -> 0.02508033 | K22: ='Home Prices (Raw Data)'!C66 -> 0.24101672
A23: 1947 | B23: 15.3 | C23: =D23*B23 -> 0.7956 | D23: 0.052 | E23: 0.0239 | F23: =((E22*(1-(1+E23)^(-10))/E23+1/(1+E23)^10)-1)+E22 -> 0.0091969681 | G23: ='Moody''s Rates'!C40 -> 0.0286 | H23: =((G22*(1-(1+G23)^(-10))/G23+1/(1+G23)^10)-1)+G22 -> 0.0046213142 | I23: ='Moody''s Rates'!K40 -> 0.0352 | J23: =((I22*(1-(1+I23)^(-10))/I23+1/(1+I23)^10)-1)+I22 -> 0.0026212023 | K23: ='Home Prices (Raw Data)'!C67 -> 0.21263835
A24: 1948 | B24: 15.2 | C24: =D24*B24 -> 0.9728 | D24: 0.064 | E24: 0.0244 | F24: =((E23*(1-(1+E24)^(-10))/E24+1/(1+E24)^10)-1)+E23 -> 0.019510369 | G24: ='Moody''s Rates'!C41 -> 0.0279 | H24: =((G23*(1-(1+G24)^(-10))/G24+1/(1+G24)^10)-1)+G23 -> 0.034635649 | I24: ='Moody''s Rates'!K41 -> 0.0353 | J24: =((I23*(1-(1+I24)^(-10))/I24+1/(1+I24)^10)-1)+I23 -> 0.034369596 | K24: ='Home Prices (Raw Data)'!C68 -> 0.020585429
... A35: 1959 | B35: 59.89 | C35: =D35*B35 -> 1.97637 | D35: 0.033 | E35: 0.0469 | F35: =((E34*(1-(1+E35)^(-10))/E35+1/(1+E35)^10)-1)+E34 -> -0.026466313 | G35: ='Moody''s Rates'!C52 -> 0.0458 | H35: =((G34*(1-(1+G35)^(-10))/G35+1/(1+G35)^10)-1)+G34 -> 0.0013915704 | I35: ='Moody''s Rates'!K52 -> 0.0528 | J35: =((I34*(1-(1+I35)^(-10))/I35+1/(1+I35)^10)-1)+I34 -> 0.015743431 | K35: ='Home Prices (Raw Data)'!C79 -> 0.0010951056
A36: 1960 | B36: 58.11 | C36: 1.981551 | D36: =C36/B35 -> 0.033086509 | E36: 0.0384 | F36: =((E35*(1-(1+E36)^(-10))/E36+1/(1+E36)^10)-1)+E35 -> 0.11639504 | G36: ='Moody''s Rates'!C53 -> 0.0435 | H36: =((G35*(1-(1+G36)^(-10))/G36+1/(1+G36)^10)-1)+G35 -> 0.064134222 | I36: ='Moody''s Rates'!K53 -> 0.051 | J36: =((I35*(1-(1+I36)^(-10))/I36+1/(1+I36)^10)-1)+I35 -> 0.066631872 | K36: ='Home Prices (Raw Data)'!C80 -> 0.0076586744
A37: 1961 | B37: 71.55 | C37: 2.039175 | D37: =C37/B36 -> 0.035091637 | E37: 0.0406 | F37: =((E36*(1-(1+E37)^(-10))/E37+1/(1+E37)^10)-1)+E36 -> 0.020609208 | G37: ='Moody''s Rates'!C54 -> 0.0442 | H37: =((G36*(1-(1+G37)^(-10))/G37+1/(1+G37)^10)-1)+G36 -> 0.037939246 | I37: ='Moody''s Rates'!K54 -> 0.051 | J37: =((I36*(1-(1+I37)^(-10))/I37+1/(1+I37)^10)-1)+I36 -> 0.051 | K37: ='Home Prices (Raw Data)'!C81 -> 0.0097716517
A38: 1962 | B38: 63.1 | C38: 2.1454 | D38: =C38/B37 -> 0.029984626 | E38: 0.0386 | F38: =((E37*(1-(1+E38)^(-10))/E38+1/(1+E38)^10)-1)+E37 -> 0.056935441 | G38: ='Moody''s Rates'!C55 -> 0.0424 | H38: =((G37*(1-(1+G38)^(-10))/G38+1/(1+G38)^10)-1)+G37 -> 0.058626733 | I38: ='Moody''s Rates'!K55 -> 0.0492 | J38: =((I37*(1-(1+I38)^(-10))/I38+1/(1+I38)^10)-1)+I37 -> 0.06495328 | K38: ='Home Prices (Raw Data)'!C82 -> 0.0032259133
A39: 1963 | B39: 75.02 | C39: 2.348126 | D39: =C39/B38 -> 0.037212773 | E39: 0.0413 | F39: =((E38*(1-(1+E39)^(-10))/E39+1/(1+E39)^10)-1)+E38 -> 0.016841621 | G39: ='Moody''s Rates'!C56 -> 0.0435 | H39: =((G38*(1-(1+G39)^(-10))/G39+1/(1+G39)^10)-1)+G38 -> 0.033631459 | I39: ='Moody''s Rates'!K56 -> 0.0485 | J39: =((I38*(1-(1+I39)^(-10))/I39+1/(1+I39)^10)-1)+I38 -> 0.054644806 | K39: ='Home Prices (Raw Data)'!C83 -> 0.021436503
A40: 1964 | B40: 84.75 | C40: 2.584875 | D40: =C40/B39 -> 0.034455812 | E40: 0.0418 | F40: =((E39*(1-(1+E40)^(-10))/E40+1/(1+E40)^10)-1)+E39 -> 0.037280649 | G40: ='Moody''s Rates'!C57 -> 0.0444 | H40: =((G39*(1-(1+G40)^(-10))/G40+1/(1+G40)^10)-1)+G39 -> 0.036357498 | I40: ='Moody''s Rates'!K57 -> 0.0481 | J40: =((I39*(1-(1+I40)^(-10))/I40+1/(1+I40)^10)-1)+I39 -> 0.051617393 | K40: ='Home Prices (Raw Data)'!C84 -> 0.012591594
A41: 1965 | B41: 92.43 | C41: 2.828358 | D41: =C41/B40 -> 0.033372956 | E41: 0.0462 | F41: =((E40*(1-(1+E41)^(-10))/E41+1/(1+E41)^10)-1)+E40 -> 0.0071885509 | G41: ='Moody''s Rates'!C58 -> 0.0468 | H41: =((G40*(1-(1+G41)^(-10))/G41+1/(1+G41)^10)-1)+G40 -> 0.025576434 | I41: ='Moody''s Rates'!K58 -> 0.0502 | J41: =((I40*(1-(1+I41)^(-10))/I41+1/(1+I41)^10)-1)+I40 -> 0.031900095 | K41: ='Home Prices (Raw Data)'!C85 -> 0.016580023
A42: 1966 | B42: 80.33 | C42: 2.883847 | D42: =C42/B41 -> 0.031200335 | E42: 0.0484 | F42: =((E41*(1-(1+E42)^(-10))/E42+1/(1+E42)^10)-1)+E41 -> 0.029079409 | G42: ='Moody''s Rates'!C59 -> 0.0539 | H42: =((G41*(1-(1+G42)^(-10))/G42+1/(1+G42)^10)-1)+G41 -> -0.0070006458 | I42: ='Moody''s Rates'!K59 -> 0.0618 | J42: =((I41*(1-(1+I42)^(-10))/I42+1/(1+I42)^10)-1)+I41 -> -0.034453616 | K42: ='Home Prices (Raw Data)'!C86 -> 0.012232822
A43: 1967 | B43: 96.47 | C43: 2.980923 | D43: =C43/B42 -> 0.037108465 | E43: 0.057 | F43: =((E42*(1-(1+E43)^(-10))/E43+1/(1+E43)^10)-1)+E42 -> -0.01580621 | G43: ='Moody''s Rates'!C60 -> 0.0619 | H43: =((G42*(1-(1+G43)^(-10))/G43+1/(1+G43)^10)-1)+G42 -> -0.0044542767 | I43: ='Moody''s Rates'!K60 -> 0.0693 | J43: =((I42*(1-(1+I43)^(-10))/I43+1/(1+I43)^10)-1)+I42 -> 0.0089522661 | K43: ='Home Prices (Raw Data)'!C87 -> 0.023161882
A44: 1968 | B44: 103.86 | C44: 3.043098 | D44: =C44/B43 -> 0.031544501 | E44: 0.0603 | F44: =((E43*(1-(1+E44)^(-10))/E44+1/(1+E44)^10)-1)+E43 -> 0.032746197 | G44: ='Moody''s Rates'!C61 -> 0.0645 | H44: =((G43*(1-(1+G44)^(-10))/G44+1/(1+G44)^10)-1)+G43 -> 0.043165229 | I44: ='Moody''s Rates'!K61 -> 0.0723 | J44: =((I43*(1-(1+I44)^(-10))/I44+1/(1+I44)^10)-1)+I43 -> 0.048451462 | K44: ='Home Prices (Raw Data)'!C88 -> 0.041338762
A45: 1969 | B45: 92.06 | C45: 3.240512 | D45: =C45/B44 -> 0.03120077 | E45: 0.0765 | F45: =((E44*(1-(1+E45)^(-10))/E45+1/(1+E45)^10)-1)+E44 -> -0.050140493 | G45: ='Moody''s Rates'!C62 -> 0.0772 | H45: =((G44*(1-(1+G45)^(-10))/G45+1/(1+G45)^10)-1)+G44 -> -0.021804851 | I45: ='Moody''s Rates'!K62 -> 0.0865 | J45: =((I44*(1-(1+I45)^(-10))/I45+1/(1+I45)^10)-1)+I44 -> -0.020251643 | K45: ='Home Prices (Raw Data)'!C89 -> 0.069943499
A46: 1970 | B46: 92.15 | C46: 3.18839 | D46: =C46/B45 -> 0.034633826 | E46: 0.0639 | F46: =((E45*(1-(1+E46)^(-10))/E46+1/(1+E46)^10)-1)+E45 -> 0.16754737 | G46: ='Moody''s Rates'!C63 -> 0.0764 | H46: =((G45*(1-(1+G46)^(-10))/G46+1/(1+G46)^10)-1)+G45 -> 0.082656334 | I46: ='Moody''s Rates'!K63 -> 0.0912 | J46: =((I45*(1-(1+I46)^(-10))/I46+1/(1+I46)^10)-1)+I45 -> 0.056495677 | K46: ='Home Prices (Raw Data)'!C90 -> 0.082154964
A47: 1971 | B47: 102.09 | C47: 3.16479 | D47: =C47/B46 -> 0.034343896 | E47: 0.0593 | F47: =((E46*(1-(1+E47)^(-10))/E47+1/(1+E47)^10)-1)+E46 -> 0.097868966 | G47: ='Moody''s Rates'!C64 -> 0.0725 | H47: =((G46*(1-(1+G47)^(-10))/G47+1/(1+G47)^10)-1)+G46 -> 0.1034782 | I47: ='Moody''s Rates'!K64 -> 0.0838 | J47: =((I46*(1-(1+I47)^(-10))/I47+1/(1+I47)^10)-1)+I46 -> 0.14001466 | K47: ='Home Prices (Raw Data)'!C91 -> 0.042449238
... A92: 2016 | B92: 2238.83 | C92: 45.7 | D92: =C92/B91 -> 0.022359215 | E92: 0.0245 | F92: =((E91*(1-(1+E92)^(-10))/E92+1/(1+E92)^10)-1)+E91 -> 0.0069055047 | G92: ='Moody''s Rates'!C109 -> 0.0398 | H92: =((G91*(1-(1+G92)^(-10))/G92+1/(1+G92)^10)-1)+G91 -> 0.045271386 | I92: ='Moody''s Rates'!K109 -> 0.0473 | J92: =((I91*(1-(1+I92)^(-10))/I92+1/(1+I92)^10)-1)+I91 -> 0.11524474 | K92: ='Home Prices (Raw Data)'!C136 -> 0.053044536
A93: 2017 | B93: 2673.61 | C93: 48.93 | D93: =C93/B92 -> 0.021855165 | E93: 0.0241 | F93: ='T. Bond yield & return'!C98 -> 0.028017163 | G93: ='Moody''s Rates'!C110 -> 0.0345 | H93: =((G92*(1-(1+G93)^(-10))/G93+1/(1+G93)^10)-1)+G92 -> 0.083989302 | I93: ='Moody''s Rates'!K110 -> 0.0418 | J93: =((I92*(1-(1+I93)^(-10))/I93+1/(1+I93)^10)-1)+I92 -> 0.091512862 | K93: ='Home Prices (Raw Data)'!C137 -> 0.062069564
A94: 2018 | B94: 2506.85 | C94: 53.75 | D94: =C94/B93 -> 0.020103904 | E94: ='T. Bond yield & return'!B99 -> 0.0269 | F94: ='T. Bond yield & return'!C99 -> -0.00016692386 | G94: ='Moody''s Rates'!C111 -> 0.0399 | H94: =((G93*(1-(1+G94)^(-10))/G94+1/(1+G94)^10)-1)+G93 -> -0.009320649 | I94: ='Moody''s Rates'!K111 -> 0.0514 | J94: =((I93*(1-(1+I94)^(-10))/I94+1/(1+I94)^10)-1)+I93 -> -0.031827246 | K94: ='Home Prices (Raw Data)'!C138 -> 0.045192288
A95: 2019 | B95: 3230.78 | C95: 58.5 | D95: =C95/B94 -> 0.023336059 | E95: 0.0192 | F95: ='T. Bond yield & return'!C100 -> 0.096356307 | G95: ='Moody''s Rates'!C112 -> 0.0304 | H95: =((G94*(1-(1+G95)^(-10))/G95+1/(1+G95)^10)-1)+G94 -> 0.12077175 | I95: ='Moody''s Rates'!K112 -> 0.039 | J95: =((I94*(1-(1+I95)^(-10))/I95+1/(1+I95)^10)-1)+I94 -> 0.15247766 | K95: ='Home Prices (Raw Data)'!C139 -> 0.036858278
...

Sheet Small Cap
A1: Year | B1: Return
A2: 1928 | B2: =C2/100 -> 0.6215 | C2: 62.15
A3: =A2+1 -> 1929 | B3: =C3/100 -> -0.4608 | C3: -46.08
A4: =A3+1 -> 1930 | B4: =C4/100 -> -0.4835 | C4: -48.35
A5: =A4+1 -> 1931 | B5: =C5/100 -> -0.4362 | C5: -43.62
A6: =A5+1 -> 1932 | B6: =C6/100 -> 0.2865 | C6: 28.65
A7: =A6+1 -> 1933 | B7: =C7/100 -> 1.466 | C7: 146.6
A8: =A7+1 -> 1934 | B8: =C8/100 -> 0.2307 | C8: 23.07
A9: =A8+1 -> 1935 | B9: =C9/100 -> 0.549 | C9: 54.9
A10: =A9+1 -> 1936 | B10: =C10/100 -> 0.9641 | C10: 96.41
A11: =A10+1 -> 1937 | B11: =C11/100 -> -0.5394 | C11: -53.94
A12: =A11+1 -> 1938 | B12: =C12/100 -> 0.0516 | C12: 5.16
A13: =A12+1 -> 1939 | B13: =C13/100 -> -0.0486 | C13: -4.86
A14: =A13+1 -> 1940 | B14: =C14/100 -> -0.3288 | C14: -32.88
... A97: =A96+1 -> 2023 | B97: =C97/100 -> 0.0519 | C97: 5.19
A98: 2024 | B98: =C98/100 -> 0.087 | C98: 8.7
A99: 2025 | B99: =C99/100 -> 0.1653 | C99: 16.53 | D99: (thru Nov 2025)

Sheet T. Bond yield & return
A1: Bond used: | B1: US treasury 10-year bond at end of each year
A2: Source: | B2: Federal Reserve of St. Louis (FRED)
A3: Computation | B3: To compute the return on a constant maturity bond, I add two components - the promised coupon at the start of the year and the price change due to interest rate changes.
B4: The return on the 10-year bond for 1928 = 3.17% (Coupon rate promised at the end of 1927) - Price change on a bond with a coupon rate of 3.17%, when the interest rate goes to 3.45%.
A7: Year | B7: T.Bond rate | C7: Return on bond
A8: 1927 | B8: 0.0317
A9: 1928 | B9: 0.0345 | C9: =((B8*(1-(1+B9)^(-10))/B9+1/(1+B9)^10)-1)+B8 -> 0.0083547086
A10: 1929 | B10: 0.0336 | C10: =((B9*(1-(1+B10)^(-10))/B10+1/(1+B10)^10)-1)+B9 -> 0.042038042
A11: 1930 | B11: 0.0322 | C11: =((B10*(1-(1+B11)^(-10))/B11+1/(1+B11)^10)-1)+B10 -> 0.045409314
A12: 1931 | B12: 0.0393 | C12: =((B11*(1-(1+B12)^(-10))/B12+1/(1+B12)^10)-1)+B11 -> -0.02558856
A13: 1932 | B13: 0.0335 | C13: =((B12*(1-(1+B13)^(-10))/B13+1/(1+B13)^10)-1)+B12 -> 0.08790307
A14: 1933 | B14: 0.0353 | C14: =((B13*(1-(1+B14)^(-10))/B14+1/(1+B14)^10)-1)+B13 -> 0.018552721
A15: 1934 | B15: 0.0301 | C15: =((B14*(1-(1+B15)^(-10))/B15+1/(1+B15)^10)-1)+B14 -> 0.079634426
A16: 1935 | B16: 0.0284 | C16: =((B15*(1-(1+B16)^(-10))/B16+1/(1+B16)^10)-1)+B15 -> 0.044720477
A17: 1936 | B17: 0.0259 | C17: =((B16*(1-(1+B17)^(-10))/B17+1/(1+B17)^10)-1)+B16 -> 0.050178754
A18: 1937 | B18: 0.0273 | C18: =((B17*(1-(1+B18)^(-10))/B18+1/(1+B18)^10)-1)+B17 -> 0.013791461
A19: 1938 | B19: 0.0256 | C19: =((B18*(1-(1+B19)^(-10))/B19+1/(1+B19)^10)-1)+B18 -> 0.042132485
A20: 1939 | B20: 0.0235 | C20: =((B19*(1-(1+B20)^(-10))/B20+1/(1+B20)^10)-1)+B19 -> 0.044122614
... A89: 2008 | B89: 0.0221 | C89: =((B88*(1-(1+B89)^(-10))/B89+1/(1+B89)^10)-1)+B88 -> 0.2010128
A90: 2009 | B90: ='S&P 500 & Raw Data'!E85 -> 0.0384 | C90: =((B89*(1-(1+B90)^(-10))/B90+1/(1+B90)^10)-1)+B89 -> -0.11116695
A91: 2010 | B91: ='S&P 500 & Raw Data'!E86 -> 0.0329 | C91: =((B90*(1-(1+B91)^(-10))/B91+1/(1+B91)^10)-1)+B90 -> 0.084629339
A92: 2011 | B92: 0.0188 | C92: =((B91*(1-(1+B92)^(-10))/B92+1/(1+B92)^10)-1)+B91 -> 0.16035335
A93: 2012 | B93: 0.0176 | C93: =((B92*(1-(1+B93)^(-10))/B93+1/(1+B93)^10)-1)+B92 -> 0.02971572
A94: 2013 | B94: 0.03036 | C94: =((B93*(1-(1+B94)^(-10))/B94+1/(1+B94)^10)-1)+B93 -> -0.091045688
A95: 2014 | B95: 0.0217 | C95: =((B94*(1-(1+B95)^(-10))/B95+1/(1+B95)^10)-1)+B94 -> 0.1074618
A96: 2015 | B96: 0.0227 | C96: =((B95*(1-(1+B96)^(-10))/B96+1/(1+B96)^10)-1)+B95 -> 0.012842997
A97: 2016 | B97: 0.0245 | C97: =((B96*(1-(1+B97)^(-10))/B97+1/(1+B97)^10)-1)+B96 -> 0.0069055047
A98: 2017 | B98: 0.0241 | C98: =((B97*(1-(1+B98)^(-10))/B98+1/(1+B98)^10)-1)+B97 -> 0.028017163
A99: 2018 | B99: 0.0269 | C99: =((B98*(1-(1+B99)^(-10))/B99+1/(1+B99)^10)-1)+B98 -> -0.00016692386
A100: 2019 | B100: 0.0192 | C100: =((B99*(1-(1+B100)^(-10))/B100+1/(1+B100)^10)-1)+B99 -> 0.096356307
A101: 2020 | B101: 0.0093 | C101: =((B100*(1-(1+B101)^(-10))/B101+1/(1+B101)^10)-1)+B100 -> 0.11331898
A102: 2021 | B102: 0.0151 | C102: =((B101*(1-(1+B102)^(-10))/B102+1/(1+B102)^10)-1)+B101 -> -0.044160344
A103: 2022 | B103: 0.0388 | C103: =((B102*(1-(1+B103)^(-10))/B103+1/(1+B103)^10)-1)+B102 -> -0.17828172
... A106: 2025 | B106: 0.0418 | C106: =((B105*(1-(1+B106)^(-10))/B106+1/(1+B106)^10)-1)+B105 -> 0.077954809

Sheet T. Bill rates
A1: FRED Graph Observations
A2: Federal Reserve Economic Data
A3: Link: https://fred.stlouisfed.org
A4: Help: https://fredhelp.stlouisfed.org
A5: Economic Research Division
A6: Federal Reserve Bank of St. Louis
A8: DTB3 | B8: 3-Month Treasury Bill Secondary Market Rate, Discount Basis, Percent, Annual, Not Seasonally Adjusted
A10: Frequency: Annual | B10: Average for the year
A11: observation_date | B11: TB3MS
A12: 1934 | B12: 0.27833333 | C12: =B12/100 -> 0.0027833333
A13: =A12+1 -> 1935 | B13: 0.1675 | C13: =B13/100 -> 0.001675
A14: =A13+1 -> 1936 | B14: 0.1725 | C14: =B14/100 -> 0.001725
A15: =A14+1 -> 1937 | B15: 0.27583333 | C15: =B15/100 -> 0.0027583333
A16: =A15+1 -> 1938 | B16: 0.065 | C16: =B16/100 -> 0.00065
A17: =A16+1 -> 1939 | B17: 0.045833333 | C17: =B17/100 -> 0.00045833333
A18: =A17+1 -> 1940 | B18: 0.035833333 | C18: =B18/100 -> 0.00035833333
A19: =A18+1 -> 1941 | B19: 0.12916667 | C19: =B19/100 -> 0.0012916667
A20: =A19+1 -> 1942 | B20: 0.3425 | C20: =B20/100 -> 0.003425
A21: =A20+1 -> 1943 | B21: 0.38 | C21: =B21/100 -> 0.0038
A22: =A21+1 -> 1944 | B22: 0.38 | C22: =B22/100 -> 0.0038
A23: =A22+1 -> 1945 | B23: 0.38 | C23: =B23/100 -> 0.0038
A24: =A23+1 -> 1946 | B24: 0.38 | C24: =B24/100 -> 0.0038
... A103: =A102+1 -> 2025 | B103: 4.21 | C103: =B103/100 -> 0.0421

Sheet Inflation Rate
A1: FRED Graph Observations
A2: Federal Reserve Economic Data
A3: Link: https://fred.stlouisfed.org
A4: Help: https://fred.stlouisfed.org/help-faq
A5: Economic Research Division
A6: Federal Reserve Bank of St. Louis
A8: CPIAUCNS | B8: Consumer Price Index for All Urban Consumers: All Items in U.S. City Average, Percent Change from Year Ago of (Index 1982-1984=100), Annual, Not Seasonally Adjusted
A10: Frequency: Annual
A11: observation_date | B11: CPIAUCNS
A12: 1914 | B12: 1 | C12: =B12/100 -> 0.01
A13: 1915 | B13: 1.9802 | C13: =B13/100 -> 0.019802
A14: =A13+1 -> 1916 | B14: 12.62136 | C14: =B14/100 -> 0.1262136
A15: =A14+1 -> 1917 | B15: 18.10345 | C15: =B15/100 -> 0.1810345
A16: =A15+1 -> 1918 | B16: 20.43796 | C16: =B16/100 -> 0.2043796
A17: =A16+1 -> 1919 | B17: 14.54545 | C17: =B17/100 -> 0.1454545
A18: =A17+1 -> 1920 | B18: 2.6455 | C18: =B18/100 -> 0.026455
A19: =A18+1 -> 1921 | B19: -10.82474 | C19: =B19/100 -> -0.1082474
A20: =A19+1 -> 1922 | B20: -2.31214 | C20: =B20/100 -> -0.0231214
A21: =A20+1 -> 1923 | B21: 2.36686 | C21: =B21/100 -> 0.0236686
A22: =A21+1 -> 1924 | B22: 0 | C22: =B22/100 -> 0
A23: =A22+1 -> 1925 | B23: 3.46821 | C23: =B23/100 -> 0.0346821
A24: =A23+1 -> 1926 | B24: -1.11732 | C24: =B24/100 -> -0.0111732
A25: =A24+1 -> 1927 | B25: -2.25989 | C25: =B25/100 -> -0.0225989
... A119: =A118+1 -> 2021 | B119: 7.0364 | C119: =B119/100 -> 0.070364
A120: 2022 | B120: 6.4544 | C120: =B120/100 -> 0.064544
A121: 2023 | B121: 3.35212 | C121: =B121/100 -> 0.0335212
A122: 2024 | B122: 2.88806 | C122: =B122/100 -> 0.0288806
A123: 2025 | B123: 2.73508 | C123: =B123/100 -> 0.0273508

Sheet Summary for ppt
A1: Nominal | G1: Real
B2: Arithmetic Average | D2: Geometric Average | H2: Arithmetic Average | J2: Geometric Average
B3: Stocks - T. Bills | C3: Stocks - T. Bonds | D3: Stocks - T. Bills | E3: Stocks - T. Bonds | H3: Stocks - T. Bills | I3: Stocks - T. Bonds | J3: Stocks - T. Bills | K3: Stocks - T. Bonds
A4: ='Returns by year'!#REF! -> #REF! | B4: ='Returns by year'!#REF!-'Returns by year'!#REF! -> #REF! | C4: ='Returns by year'!#REF! -> #REF! | D4: ='Returns by year'!#REF! -> #REF! | E4: ='Returns by year'!#REF! -> #REF! | G4: 1928-2023 | H4: ='Returns by year'!#REF!-'Returns by year'!#REF! -> #REF! | I4: ='Returns by year'!#REF!-'Returns by year'!#REF! -> #REF! | J4: ='Returns by year'!#REF!-'Returns by year'!#REF! -> #REF! | K4: ='Returns by year'!#REF!-'Returns by year'!#REF! -> #REF!
A5: Std Error | B5: ='Returns by year'!#REF! -> #REF! | C5: ='Returns by year'!#REF! -> #REF! | G5: Std Error | H5: ='Returns by year'!#REF! -> #REF! | I5: ='Returns by year'!#REF! -> #REF!
A6: ='Returns by year'!#REF! -> #REF! | B6: ='Returns by year'!#REF! -> #REF! | C6: ='Returns by year'!#REF! -> #REF! | D6: ='Returns by year'!#REF! -> #REF! | E6: ='Returns by year'!#REF! -> #REF! | G6: 1974-2023 | H6: ='Returns by year'!#REF!-'Returns by year'!#REF! -> #REF! | I6: ='Returns by year'!#REF!-'Returns by year'!#REF! -> #REF! | J6: ='Returns by year'!#REF!-'Returns by year'!#REF! -> #REF! | K6: ='Returns by year'!#REF!-'Returns by year'!#REF! -> #REF!
A7: Std Error | B7: ='Returns by year'!#REF! -> #REF! | C7: ='Returns by year'!#REF! -> #REF! | G7: Std Error | H7: ='Returns by year'!#REF! -> #REF! | I7: ='Returns by year'!#REF! -> #REF!
A8: ='Returns by year'!#REF! -> #REF! | B8: ='Returns by year'!#REF! -> #REF! | C8: ='Returns by year'!#REF! -> #REF! | D8: ='Returns by year'!#REF! -> #REF! | E8: ='Returns by year'!#REF! -> #REF! | G8: 2014-2023 | H8: ='Returns by year'!#REF!-'Returns by year'!#REF! -> #REF! | I8: ='Returns by year'!#REF!-'Returns by year'!#REF! -> #REF! | J8: ='Returns by year'!#REF!-'Returns by year'!#REF! -> #REF! | K8: ='Returns by year'!#REF!-'Returns by year'!#REF! -> #REF!
A9: Std Error | B9: ='Returns by year'!#REF! -> #REF! | C9: ='Returns by year'!#REF! -> #REF! | G9: Std Error | H9: ='Returns by year'!#REF! -> #REF! | I9: 0.038564857

Sheet Home Prices (Raw Data)
A1: Home Price data from Robert Shiller's website. | F1: FRED Graph Observations
F2: Federal Reserve Economic Data
F3: Link: https://fred.stlouisfed.org
F4: Help: https://fred.stlouisfed.org/help-faq
F5: Economic Research Division
F6: Federal Reserve Bank of St. Louis
F8: CSUSHPINSA | G8: S&P/Case-Shiller U.S. National Home Price Index, Percent Change from Year Ago of (Index Jan 2000=100), Annual, Not Seasonally Adjusted
A9: Date | B9: From fig2.1Revised2011.xls | C9: Chg in House Price
A10: 1890 | B10: 3.557296 | F10: Frequency: Annual
A11: 1891 | B11: 3.209111 | C11: =B11/B10-1 -> -0.097879119 | F11: observation_date | G11: CSUSHPINSA
A12: 1892 | B12: 3.267142 | C12: =B12/B11-1 -> 0.018083201 | F12: 30681 | G12: 7.21643 | H12: =G12/100 -> 0.0721643
A13: 1893 | B13: 3.406416 | C13: =B13/B12-1 -> 0.042628695 | F13: 31047 | G13: 4.39434 | H13: =G13/100 -> 0.0439434
A14: 1894 | B14: 3.969316 | C14: =B14/B13-1 -> 0.16524699 | F14: 31412 | G14: -0.68762 | H14: =G14/100 -> -0.0068762
A15: 1895 | B15: 3.603721 | C15: =B15/B14-1 -> -0.09210529 | F15: 31777 | G15: -0.17112 | H15: =G15/100 -> -0.0017112
A16: 1896 | B16: 3.122064 | C16: =B16/B15-1 -> -0.13365546 | F16: 32142 | G16: 0.8241 | H16: =G16/100 -> 0.008241
A17: 1897 | B17: 3.220717 | C17: =B17/B16-1 -> 0.031598648 | F17: 32508 | G17: 2.15785 | H17: =G17/100 -> 0.0215785
A18: 1898 | B18: 3.429628 | C18: =B18/B17-1 -> 0.064864749 | F18: 32873 | G18: 2.51296 | H18: =G18/100 -> 0.0251296
A19: 1899 | B19: 3.278748 | C19: =B19/B18-1 -> -0.043993109 | F19: 33238 | G19: 1.792 | H19: =G19/100 -> 0.01792
A20: 1900 | B20: 3.748799 | C20: =B20/B19-1 -> 0.14336295 | F20: 33603 | G20: 2.42538 | H20: =G20/100 -> 0.0242538
A21: 1901 | B21: 3.145277 | C21: =B21/B20-1 -> -0.16099076 | F21: 33969 | G21: 4.02324 | H21: =G21/100 -> 0.0402324
A22: 1902 | B22: 3.708177 | C22: =B22/B21-1 -> 0.17896675 | F22: 34334 | G22: 6.44106 | H22: =G22/100 -> 0.0644106
A23: 1903 | B23: 3.766208 | C23: =B23/B22-1 -> 0.015649469 | F23: 34699 | G23: 7.67933 | H23: =G23/100 -> 0.0767933
... A48: 1928 | B48: 5.924959 | C48: =B48/B47-1 -> 0.014910639 | F48: 43830 | G48: 3.99919 | H48: =G48/100 -> 0.0399919
A49: 1929 | B49: 5.803094 | C49: =B49/B48-1 -> -0.020568075
A50: 1930 | B50: 5.553561 | C50: =B50/B49-1 -> -0.042999993
A51: 1931 | B51: 5.100919 | C51: =B51/B50-1 -> -0.081504822
A52: 1932 | B52: 4.567035 | C52: =B52/B51-1 -> -0.10466428
A53: 1933 | B53: 4.392942 | C53: =B53/B52-1 -> -0.03811948
A54: 1934 | B54: 4.52061 | C54: =B54/B53-1 -> 0.029062073
A55: 1935 | B55: 4.962085 | C55: =B55/B54-1 -> 0.097658281
A56: 1936 | B56: 5.121795 | C56: =B56/B55-1 -> 0.032186067
A57: 1937 | B57: 5.253087 | C57: =B57/B56-1 -> 0.025633982
A58: 1938 | B58: 5.207191 | C58: =B58/B57-1 -> -0.0087369579
A59: 1939 | B59: 5.139414 | C59: =B59/B58-1 -> -0.013016039
A60: 1940 | B60: 5.309354 | C60: =B60/B59-1 -> 0.033066027
... A72: 1952 | B72: 12.87695 | C72: =B72/B71-1 -> 0.044066304
A73: =A72+1 -> 1953 | B73: 14.35994 | C73: =B73/B72-1 -> 0.11516625
A74: =A73+1 -> 1954 | B74: 14.49244 | C74: =B74/B73-1 -> 0.0092270581
A75: =A74+1 -> 1955 | B75: 14.49244 | C75: =B75/B74-1 -> 0
A76: =A75+1 -> 1956 | B76: 14.62494 | C76: =B76/B75-1 -> 0.0091426978
...

Sheet Moody's Rates
A1: FRED Graph Observations | I1: FRED Graph Observations
A2: Federal Reserve Economic Data | I2: Federal Reserve Economic Data
A3: Link: https://fred.stlouisfed.org | I3: Link: https://fred.stlouisfed.org
A4: Help: https://fred.stlouisfed.org/help-faq | I4: Help: https://fred.stlouisfed.org/help-faq
A5: Economic Research Division | I5: Economic Research Division
A6: Federal Reserve Bank of St. Louis | I6: Federal Reserve Bank of St. Louis
A8: AAA | B8: Moody's Seasoned Aaa Corporate Bond Yield, Percent, Annual, Not Seasonally Adjusted | I8: BAA | J8: Moody's Seasoned Baa Corporate Bond Yield, Percent, Annual, Not Seasonally Adjusted
A10: Frequency: Annual | I10: Frequency: Annual
A11: observation_date | B11: AAA | C11: % Rate | I11: observation_date | J11: BAA
A12: 1919 | B12: 5.73 | C12: =B12/100 -> 0.0573 | I12: 1919 | J12: 7.77 | K12: =J12/100 -> 0.0777
A13: =A12+1 -> 1920 | B13: 6.26 | C13: =B13/100 -> 0.0626 | I13: =I12+1 -> 1920 | J13: 8.56 | K13: =J13/100 -> 0.0856
A14: =A13+1 -> 1921 | B14: 5.5 | C14: =B14/100 -> 0.055 | I14: =I13+1 -> 1921 | J14: 7.61 | K14: =J14/100 -> 0.0761
A15: =A14+1 -> 1922 | B15: 5.08 | C15: =B15/100 -> 0.0508 | I15: =I14+1 -> 1922 | J15: 7.02 | K15: =J15/100 -> 0.0702
A16: =A15+1 -> 1923 | B16: 5.09 | C16: =B16/100 -> 0.0509 | I16: =I15+1 -> 1923 | J16: 7.38 | K16: =J16/100 -> 0.0738
A17: =A16+1 -> 1924 | B17: 4.95 | C17: =B17/100 -> 0.0495 | I17: =I16+1 -> 1924 | J17: 6.46 | K17: =J17/100 -> 0.0646
A18: =A17+1 -> 1925 | B18: 4.85 | C18: =B18/100 -> 0.0485 | I18: =I17+1 -> 1925 | J18: 6.15 | K18: =J18/100 -> 0.0615
A19: =A18+1 -> 1926 | B19: 4.68 | C19: =B19/100 -> 0.0468 | I19: =I18+1 -> 1926 | J19: 5.68 | K19: =J19/100 -> 0.0568
A20: =A19+1 -> 1927 | B20: 4.46 | C20: =B20/100 -> 0.0446 | I20: =I19+1 -> 1927 | J20: 5.32 | K20: =J20/100 -> 0.0532
A21: =A20+1 -> 1928 | B21: 4.61 | C21: =B21/100 -> 0.0461 | I21: =I20+1 -> 1928 | J21: 5.6 | K21: =J21/100 -> 0.056
A22: =A21+1 -> 1929 | B22: 4.67 | C22: =B22/100 -> 0.0467 | I22: =I21+1 -> 1929 | J22: 5.95 | K22: =J22/100 -> 0.0595
A23: =A22+1 -> 1930 | B23: 4.52 | C23: =B23/100 -> 0.0452 | I23: =I22+1 -> 1930 | J23: 6.71 | K23: =J23/100 -> 0.0671
A24: =A23+1 -> 1931 | B24: 5.32 | C24: =B24/100 -> 0.0532 | I24: =I23+1 -> 1931 | J24: 10.42 | K24: =J24/100 -> 0.1042
... A78: =A77+1 -> 1985 | B78: 9.91 | C78: =B78/100 -> 0.0991 | I78: =I77+1 -> 1985 | J78: 11.58 | K78: =J78/100 -> 0.1158
A79: =A78+1 -> 1986 | B79: 8.53 | C79: =B79/100 -> 0.0853 | I79: =I78+1 -> 1986 | K79: =O79+M79/100 -> 0.0987 | M79: 2.76 | O79: 0.0711
A80: =A79+1 -> 1987 | B80: 10.06 | C80: =B80/100 -> 0.1006 | I80: =I79+1 -> 1987 | K80: =O80+M80/100 -> 0.1138 | M80: 2.39 | O80: 0.0899
A81: =A80+1 -> 1988 | B81: 9.61 | C81: =B81/100 -> 0.0961 | I81: =I80+1 -> 1988 | K81: =O81+M81/100 -> 0.1066 | M81: 1.55 | O81: 0.0911
A82: =A81+1 -> 1989 | B82: 8.87 | C82: =B82/100 -> 0.0887 | I82: =I81+1 -> 1989 | K82: =O82+M82/100 -> 0.0975 | M82: 1.91 | O82: 0.0784
A83: =A82+1 -> 1990 | B83: 9.05 | C83: =B83/100 -> 0.0905 | I83: =I82+1 -> 1990 | K83: =O83+M83/100 -> 0.1043 | M83: 2.35 | O83: 0.0808
A84: =A83+1 -> 1991 | B84: 8.16 | C84: =B84/100 -> 0.0816 | I84: =I83+1 -> 1991 | K84: =O84+M84/100 -> 0.0948 | M84: 2.39 | O84: 0.0709
A85: =A84+1 -> 1992 | B85: 7.91 | C85: =B85/100 -> 0.0791 | I85: =I84+1 -> 1992 | K85: =O85+M85/100 -> 0.0883 | M85: 2.06 | O85: 0.0677
A86: =A85+1 -> 1993 | B86: 7 | C86: =B86/100 -> 0.07 | I86: =I85+1 -> 1993 | K86: =O86+M86/100 -> 0.0771 | M86: 1.94 | O86: 0.0577
A87: =A86+1 -> 1994 | B87: 8.49 | C87: =B87/100 -> 0.0849 | I87: =I86+1 -> 1994 | K87: =O87+M87/100 -> 0.0911 | M87: 1.3 | O87: 0.0781
A88: =A87+1 -> 1995 | B88: 6.71 | C88: =B88/100 -> 0.0671 | I88: =I87+1 -> 1995 | K88: =O88+M88/100 -> 0.0751 | M88: 1.8 | O88: 0.0571
A89: =A88+1 -> 1996 | B89: 7.27 | C89: =B89/100 -> 0.0727 | I89: =I88+1 -> 1996 | K89: =O89+M89/100 -> 0.0784 | M89: 1.54 | O89: 0.063
A90: =A89+1 -> 1997 | B90: 6.71 | C90: =B90/100 -> 0.0671 | I90: =I89+1 -> 1997 | K90: =O90+M90/100 -> 0.0734 | M90: 1.53 | O90: 0.0581
... A118: =A117+1 -> 2025 | B118: 5.31 | C118: =B118/100 -> 0.0531 | I118: =I117+1 -> 2025 | K118: =O118+M118/100 -> 0.0587 | M118: 1.75 | O118: 0.0412

Sheet Home Prices
A2: End of year | B2: Real Estate | D2: Source of data: | E2: http://www.econ.yale.edu//~shiller/data.htm
A3: 1927 | B3: 5.8379123
A4: 1928 | B4: 5.9249587 | D4: Source for 1977 - Current: Case Shiller index (FRED) | E4: https://fred.stlouisfed.org/series/CSUSHPINSA
A5: 1929 | B5: 5.8030937
A6: 1930 | B6: 5.5535607
A7: 1931 | B7: 5.1009194
A8: 1932 | B8: 4.5670348
A9: 1933 | B9: 4.3929419
A10: 1934 | B10: 4.52061
A11: 1935 | B11: 4.9620853
A12: 1936 | B12: 5.121795
A13: 1937 | B13: 5.2530867
A14: 1938 | B14: 5.2071914
A15: 1939 | B15: 5.1394142
A16: 1940 | B16: 5.3093545
... A28: 1952 | B28: 12.876954
A29: =A28+1 -> 1953 | B29: 14.359937
A30: =A29+1 -> 1954 | B30: 14.492439
A31: =A30+1 -> 1955 | B31: 14.492439
A32: =A31+1 -> 1956 | B32: 14.624941
A33: =A32+1 -> 1957 | B33: 15.022448
A34: =A33+1 -> 1958 | B34: 15.121825
A35: =A34+1 -> 1959 | B35: 15.138388
A36: =A35+1 -> 1960 | B36: 15.254327
A37: =A36+1 -> 1961 | B37: 15.403393
A38: =A37+1 -> 1962 | B38: 15.453081
A39: =A38+1 -> 1963 | B39: 15.784337
A40: =A39+1 -> 1964 | B40: 15.98309
... A96: =A95+1 -> 2020 | B96: 234.354
A97: 2021 | B97: 278.564
A98: 2022 | B98: 294.308
A99: 2023 | B99: 311.02
A100: 2025 | B100: 323.347
A101: 328.442 | B101: 328.442

Sheet Gold Prices
A1: Year | B1: Price per oz | E1: Source for pre-1970: https://nma.org/wp-content/uploads/2016/09/historic_gold_prices_1833_pres.pdf (average price for year)
A2: 1927 | B2: 20.64 | E2: Source for 1970-Current: LBMA Gold prices per oz
A3: 1928 | B3: 20.66
A4: =A3+1 -> 1929 | B4: 20.63
A5: =A4+1 -> 1930 | B5: 20.65
A6: =A5+1 -> 1931 | B6: 17.06
A7: =A6+1 -> 1932 | B7: 20.69
A8: =A7+1 -> 1933 | B8: 26.33
A9: =A8+1 -> 1934 | B9: 34.69
A10: =A9+1 -> 1935 | B10: 34.84
A11: =A10+1 -> 1936 | B11: 34.87
A12: =A11+1 -> 1937 | B12: 34.79
A13: =A12+1 -> 1938 | B13: 34.85
A14: =A13+1 -> 1939 | B14: 34.42
A15: =A14+1 -> 1940 | B15: 33.85
... A43: =A42+1 -> 1968 | B43: 39.31
A44: 1969 | B44: 41.28
A45: 1970 | B45: 37.38
A46: 1971 | B46: 43.62
A47: =A46+1 -> 1972 | B47: 64.9
A48: =A47+1 -> 1973 | B48: 112.25
A49: =A48+1 -> 1974 | B49: 186.5
A50: =A49+1 -> 1975 | B50: 140.25
A51: =A50+1 -> 1976 | B51: 134.5
A52: =A51+1 -> 1977 | B52: 164.95
A53: =A52+1 -> 1978 | B53: 226
A54: =A53+1 -> 1979 | B54: 512
A55: =A54+1 -> 1980 | B55: 589.75
A56: =A55+1 -> 1981 | B56: 397.5
A57: =A56+1 -> 1982 | B57: 459.6
A58: =A57+1 -> 1983 | B58: 382.4
... A97: =A96+1 -> 2022 | B97: 1830.1
A98: 2023 | B98: 2072.81
A99: 2024 | B99: 2610.85
A100: 2025 | B100: 4339.645

Sheet Nominal vs Real Data
A1: Year | B1: S&P 500 (includes dividends) | C1: 3-month T.Bill | D1: US T. Bond (10-year) | E1: Inflation Rate | F1: S&P 500 (Real) | G1: T. Bill (Real) | H1: T.Bond (Real) | I1: Year | J1: Nominal value of $100 invested in 1928 | K1: Real value of $100 invested in 1928 | P1: Stocks | Q1: T. Bills | R1: T. Bonds
A2: 1928 | B2: 0.43811155 | C2: 0.0308 | D2: 0.0083547086 | E2: -0.0115607 | F2: 0.45493158 | G2: 0.042856147 | H2: 0.020148337 | I2: 1928 | J2: =100*(1+B2) -> 143.81116 | K2: =100*(1+F2) -> 145.49316 | O2: Mean | P2: 0.1166 | Q2: 0.0334 | R2: 0.0486
A3: 1929 | B3: -0.082979466 | C3: 0.0316 | D3: 0.042038042 | E3: 0.005848 | F3: -0.088311023 | G3: 0.025602278 | H3: 0.035979633 | I3: 1929 | J3: =J2*(1+B3) -> 131.87778 | K3: =K2*(1+F4) -> 116.38309 | O3: Standard Error | P3: 0.02 | Q3: 0.0031 | R3: 0.0081
A4: 1930 | B4: -0.25123636 | C4: 0.0455 | D4: 0.045409314 | E4: -0.0639535 | F4: -0.20007859 | G4: 0.11693169 | H4: 0.11683481 | I4: 1930 | J4: =J3*(1+B4) -> 98.745288 | K4: =K3*(1+F5) -> 72.079035 | O4: Median | P4: 0.1452 | Q4: 0.0294 | R4: 0.0328
A5: 1931 | B5: -0.43837549 | C5: 0.0231 | D5: -0.02558856 | E5: -0.0931677 | F5: -0.38067434 | G5: 0.12821301 | H5: 0.074522203 | I5: 1931 | J5: =J4*(1+B5) -> 55.457774 | K5: =K4*(1+F6) -> 73.389742 | O5: Standard Deviation | P5: 0.1955 | Q5: 0.0301 | R5: 0.0795
A6: 1932 | B6: -0.086423645 | C6: 0.0107 | D6: 0.08790307 | E6: -0.1027397 | F6: 0.018184305 | G6: 0.12642897 | H6: 0.21247209 | I6: 1932 | J6: =J5*(1+B6) -> 50.664911 | K6: =K5*(1+F7) -> 109.23769 | O6: Kurtosis | P6: 2.9816 | Q6: 3.8457 | R6: 4.6461
A7: 1933 | B7: 0.49982225 | C7: 0.0096 | D7: 0.018552721 | E7: 0.0076336 | F7: 0.48845995 | G7: 0.001951503 | H7: 0.0108364 | I7: 1933 | J7: =J6*(1+B7) -> 75.988361 | K7: =K6*(1+F8) -> 106.3283 | O7: Skewness | P7: -0.431 | Q7: 1.0153 | R7: 0.6926
A8: 1934 | B8: -0.011885657 | C8: 0.0027833333 | D8: 0.079634426 | E8: 0.0151515 | F8: -0.026633618 | G8: -0.012183567 | H8: 0.063520495 | I8: 1934 | J8: =J7*(1+B8) -> 75.085189 | K8: =K7*(1+F9) -> 151.50409 | O8: Minimum | P8: -0.4384 | Q8: 0.0003 | R8: -0.1783
A9: 1935 | B9: 0.46740421 | C9: 0.001675 | D9: 0.044720477 | E9: 0.0298507 | F9: 0.42487082 | G9: -0.027359014 | H9: 0.01443877 | I9: 1935 | J9: =J8*(1+B9) -> 110.18032 | K9: =K8*(1+F10) -> 197.04394 | O9: Maximum | P9: 0.5256 | Q9: 0.1404 | R9: 0.3281
A10: 1936 | B10: 0.3194341 | C10: 0.001725 | D10: 0.050178754 | E10: 0.0144928 | F10: 0.30058498 | G10: -0.012585402 | H10: 0.035176153 | I10: 1936 | J10: =J9*(1+B10) -> 145.37568 | K10: =K9*(1+F11) -> 123.87575 | O10: 25th percentile | P10: =-1.19% -> -0.0119 | Q10: 0.0085 | R10: 0.0081
A11: 1937 | B11: -0.35336729 | C11: 0.0027583333 | D11: 0.013791461 | E11: 0.0285714 | F11: -0.37132929 | G11: -0.025096038 | H11: -0.014369386 | I11: 1937 | J11: =J10*(1+B11) -> 94.004668 | K11: =K10*(1+F12) -> 164.72558 | O11: 75th percentile | P11: 0.2597 | Q11: 0.0506 | R11: 0.0854
A12: 1938 | B12: 0.29282654 | C12: 0.00065 | D12: 0.042132485 | E12: -0.0277778 | F12: 0.32976447 | G12: 0.029240024 | H12: 0.071907724 | I12: 1938 | J12: =J11*(1+B12) -> 121.53173 | K12: =K11*(1+F13) -> 162.91761
A13: 1939 | B13: -0.010975647 | C13: 0.00045833333 | D13: 0.044122614 | E13: 0 | F13: -0.010975647 | G13: 0.00045833333 | H13: 0.044122614 | I13: 1939 | J13: =J12*(1+B13) -> 120.19784 | K13: =K12*(1+F14) -> 144.49749
A14: 1940 | B14: -0.10672873 | C14: 0.00035833333 | D14: 0.054024816 | E14: 0.0071429 | F14: -0.11306403 | G14: -0.0067364489 | H14: 0.046549418 | I14: 1940 | J14: =J13*(1+B14) -> 107.36928 | K14: =K13*(1+F15) -> 114.65852
A15: 1941 | B15: -0.12771456 | C15: 0.0012916667 | D15: -0.020221976 | E15: 0.0992908 | F15: -0.20650164 | G15: -0.089147597 | H15: -0.10871807 | I15: 1941 | J15: =J14*(1+B15) -> 93.656657 | K15: =K14*(1+F16) -> 125.32334
A16: 1942 | B16: 0.19173763 | C16: 0.003425 | D16: 0.022948682 | E16: 0.0903226 | F16: 0.093013783 | G16: -0.079698981 | H16: -0.061792645 | I16: 1942 | J16: =J15*(1+B16) -> 111.61416 | K16: =K15*(1+F17) -> 152.22725
A17: 1943 | B17: 0.2506131 | C17: 0.0038 | D17: 0.0249 | E17: 0.0295858 | F17: 0.21467594 | G17: -0.025044829 | H17: -0.0045511506 | I17: 1943 | J17: =J16*(1+B17) -> 139.58613 | K17: =K16*(1+F18) -> 177.12528
A18: 1944 | B18: 0.19030677 | C18: 0.0038 | D18: 0.025776112 | E18: 0.0229885 | F18: 0.16355831 | G18: -0.018757298 | H18: 0.0027249686 | I18: 1944 | J18: =J17*(1+B18) -> 166.15032 | K18: =K17*(1+F19) -> 235.28615
A19: 1945 | B19: 0.35821084 | C19: 0.0038 | D19: 0.038044173 | E19: 0.0224719 | F19: 0.32836007 | G19: -0.018261529 | H19: 0.015230026 | I19: 1945 | J19: =J18*(1+B19) -> 225.66717 | K19: =K18*(1+F20) -> 182.38392
A20: 1946 | B20: -0.084291475 | C20: 0.0038 | D20: 0.031283745 | E20: 0.1813187 | F20: -0.2248421 | G20: -0.15027164 | H20: -0.12700633 | I20: 1946 | J20: =J19*(1+B20) -> 206.64535 | K20: =K19*(1+F21) -> 176.28886
A21: 1947 | B21: 0.052 | C21: 0.0060083333 | D21: 0.0091969681 | E21: 0.0883721 | F21: -0.03341881 | G21: -0.07567611 | H21: -0.072746381 | I21: 1947 | J21: =J20*(1+B21) -> 217.39091 | K21: =K20*(1+F22) -> 181.38652
A22: 1948 | B22: 0.057045752 | C22: 0.01045 | D22: 0.019510369 | E22: 0.0273387 | F22: 0.028916512 | G22: -0.016439272 | H22: -0.0076200094 | I22: 1948 | J22: =J21*(1+B22) -> 229.79213 | K22: =K21*(1+F23) -> 218.58516
A23: 1949 | B23: 0.18303224 | C23: 0.01115 | D23: 0.046634852 | E23: -0.0182952 | F23: 0.20507941 | G23: 0.029993945 | H23: 0.066140098 | I23: 1949 | J23: =J22*(1+B23) -> 271.8515 | K23: =K22*(1+F24) -> 270.24045
... A97: 2023 | B97: 0.26060685 | C97: 0.050703614 | D97: 0.0388 | E97: 0.0312 | F97: 0.22246591 | G97: 0.018913513 | H97: 0.0073700543 | I97: 2023 | J97: =J96*(1+B97) -> 787018.53 | K97: =K96*(1+F98) -> #REF!
A98: ='Returns by year'!A99 -> 2024 | B98: ='Returns by year'!B99 -> 0.24878611 | C98: ='Returns by year'!D99 -> 0.0518 | D98: ='Returns by year'!E99 -> -0.016371801 | E98: ='Returns by year'!#REF! -> #REF! | F98: ='Returns by year'!#REF! -> #REF! | G98: ='Returns by year'!#REF! -> #REF! | H98: ='Returns by year'!#REF! -> #REF! | I98: =A98 -> 2024 | J98: =J97*(1+B98) -> 982817.82 | K98: =K97*(1+F99) -> #REF!
A99: ='Returns by year'!A100 -> 2025 | B99: ='Returns by year'!B100 -> 0.17723658 | C99: ='Returns by year'!D100 -> 0.0421 | D99: ='Returns by year'!E100 -> 0.077954809 | E99: ='Returns by year'!#REF! -> #REF! | F99: ='Returns by year'!#REF! -> #REF! | G99: ='Returns by year'!#REF! -> #REF! | H99: ='Returns by year'!#REF! -> #REF! | I99: =A99 -> 2025 | J99: =J98*(1+B99) -> 1157009.1 | K99: =K98*(1+F100) -> #REF!

Sheet Sheet11

Sheet Sheet12

Sheet Sheet13

Sheet Sheet14

Sheet Sheet15

Sheet Sheet16
